2018-08-26 15:11:57 ERROR (MainThread) [homeassistant.core] Timer got out of sync. Resetting
2018-08-26 15:12:01 WARNING (SyncWorker_4) [netdisco.ssdp] Error fetching description at 192.168.86.73
2018-08-26 15:12:03 WARNING (SyncWorker_4) [netdisco.ssdp] Found malformed XML at http://192.168.86.249:9080: status=ok
2018-08-26 15:12:13 ERROR (MainThread) [homeassistant.components.media_player] Error while setting up platform plex
Traceback (most recent call last):
  File "/home/ha/homeassistant/lib/python3.6/site-packages/urllib3/connection.py", line 171, in _new_conn
    (self._dns_host, self.port), self.timeout, **extra_kw)
  File "/home/ha/homeassistant/lib/python3.6/site-packages/urllib3/util/connection.py", line 79, in create_connection
    raise err
  File "/home/ha/homeassistant/lib/python3.6/site-packages/urllib3/util/connection.py", line 69, in create_connection
    sock.connect(sa)
OSError: [Errno 113] No route to host

During handling of the above exception, another exception occurred:

Traceback (most recent call last):
  File "/home/ha/homeassistant/lib/python3.6/site-packages/urllib3/connectionpool.py", line 600, in urlopen
    chunked=chunked)
  File "/home/ha/homeassistant/lib/python3.6/site-packages/urllib3/connectionpool.py", line 354, in _make_request
    conn.request(method, url, **httplib_request_kw)
  File "/usr/lib/python3.6/http/client.py", line 1239, in request
    self._send_request(method, url, body, headers, encode_chunked)
  File "/usr/lib/python3.6/http/client.py", line 1285, in _send_request
    self.endheaders(body, encode_chunked=encode_chunked)
  File "/usr/lib/python3.6/http/client.py", line 1234, in endheaders
    self._send_output(message_body, encode_chunked=encode_chunked)
  File "/usr/lib/python3.6/http/client.py", line 1026, in _send_output
    self.send(msg)
  File "/usr/lib/python3.6/http/client.py", line 964, in send
    self.connect()
  File "/home/ha/homeassistant/lib/python3.6/site-packages/urllib3/connection.py", line 196, in connect
    conn = self._new_conn()
  File "/home/ha/homeassistant/lib/python3.6/site-packages/urllib3/connection.py", line 180, in _new_conn
    self, "Failed to establish a new connection: %s" % e)
urllib3.exceptions.NewConnectionError: <urllib3.connection.HTTPConnection object at 0x7fc489d4f080>: Failed to establish a new connection: [Errno 113] No route to host

During handling of the above exception, another exception occurred:

Traceback (most recent call last):
  File "/home/ha/homeassistant/lib/python3.6/site-packages/requests/adapters.py", line 445, in send
    timeout=timeout
  File "/home/ha/homeassistant/lib/python3.6/site-packages/urllib3/connectionpool.py", line 638, in urlopen
    _stacktrace=sys.exc_info()[2])
  File "/home/ha/homeassistant/lib/python3.6/site-packages/urllib3/util/retry.py", line 398, in increment
    raise MaxRetryError(_pool, url, error or ResponseError(cause))
urllib3.exceptions.MaxRetryError: HTTPConnectionPool(host='192.168.86.62', port=32400): Max retries exceeded with url: / (Caused by NewConnectionError('<urllib3.connection.HTTPConnection object at 0x7fc489d4f080>: Failed to establish a new connection: [Errno 113] No route to host',))

During handling of the above exception, another exception occurred:

Traceback (most recent call last):
  File "/home/ha/homeassistant/lib/python3.6/site-packages/homeassistant/helpers/entity_platform.py", line 129, in _async_setup_platform
    SLOW_SETUP_MAX_WAIT, loop=hass.loop)
  File "/usr/lib/python3.6/asyncio/tasks.py", line 358, in wait_for
    return fut.result()
  File "/usr/lib/python3.6/concurrent/futures/thread.py", line 56, in run
    result = self.fn(*self.args, **self.kwargs)
  File "/home/ha/homeassistant/lib/python3.6/site-packages/homeassistant/components/media_player/plex.py", line 101, in setup_platform
    hass, config, add_devices_callback
  File "/home/ha/homeassistant/lib/python3.6/site-packages/homeassistant/components/media_player/plex.py", line 120, in setup_plexserver
    token, cert_session
  File "/home/ha/homeassistant/lib/python3.6/site-packages/plexapi/server.py", line 102, in __init__
    data = self.query(self.key, timeout=timeout)
  File "/home/ha/homeassistant/lib/python3.6/site-packages/plexapi/server.py", line 341, in query
    response = method(url, headers=headers, timeout=timeout, **kwargs)
  File "/home/ha/homeassistant/lib/python3.6/site-packages/requests/sessions.py", line 525, in get
    return self.request('GET', url, **kwargs)
  File "/home/ha/homeassistant/lib/python3.6/site-packages/requests/sessions.py", line 512, in request
    resp = self.send(prep, **send_kwargs)
  File "/home/ha/homeassistant/lib/python3.6/site-packages/requests/sessions.py", line 622, in send
    r = adapter.send(request, **kwargs)
  File "/home/ha/homeassistant/lib/python3.6/site-packages/requests/adapters.py", line 513, in send
    raise ConnectionError(e, request=request)
requests.exceptions.ConnectionError: HTTPConnectionPool(host='192.168.86.62', port=32400): Max retries exceeded with url: / (Caused by NewConnectionError('<urllib3.connection.HTTPConnection object at 0x7fc489d4f080>: Failed to establish a new connection: [Errno 113] No route to host',))
2018-08-26 15:32:58 WARNING (SyncWorker_3) [netdisco.ssdp] Found malformed XML at http://192.168.86.93:9080: status=ok
2018-08-26 15:38:11 WARNING (SyncWorker_8) [netdisco.ssdp] Found malformed XML at http://192.168.86.39:9080: status=ok
2018-08-26 16:11:49 ERROR (MainThread) [homeassistant.components.updater] Got unexpected response: None
2018-08-26 16:25:21 WARNING (SyncWorker_8) [netdisco.ssdp] Found malformed XML at http://192.168.86.26:9080: status=ok
